<?xml version="1.0" encoding="utf-8"?>
<!-- This URDF was automatically created by SolidWorks to URDF Exporter! Originally created by Stephen Brawner (brawner@gmail.com) 
     Commit Version: 1.5.1-0-g916b5db  Build Version: 1.5.7152.31018
     For more information, please see http://wiki.ros.org/sw_urdf_exporter -->
<robot
  name="assembly_kuka_simp">
  <link
    name="base_link">
    <inertial>
      <origin
        xyz="-0.001558 2.0188E-06 0.11237"
        rpy="0 0 0" />
      <mass
        value="149.06" />
      <inertia
        ixx="1.6321"
        ixy="-1.1451E-05"
        ixz="0.012034"
        iyy="1.6721"
        iyz="3.1139E-05"
        izz="2.0397" />
    </inertial>
    <visual>
      <origin
        xyz="-0.001558 2.0188E-06 0.11237"
        rpy="0 0 0" />
      <geometry>
        <mesh
          filename="package://assembly_kuka_simp/meshes/base_link.dae" />
      </geometry>
      <material
        name="black">
        <color
          rgba="0.64706 0.61961 0.58824 1" />
      </material>
    </visual>
    <collision>
      <origin
        xyz="0 0 0"
        rpy="0 0 0" />
      <geometry>
        <mesh
          filename="package://assembly_kuka_simp/meshes/base_link.dae" />
      </geometry>
    </collision>
  </link>
 
  <link
    name="link_1">
    <inertial>
      <origin
        xyz="0 0 0"
        rpy="0 0 0" />
      <mass
        value="85.97" />
      <inertia
        ixx="1.62"
        ixy="-0.21"
        ixz="0.94"
        iyy="2.57"
        iyz="-0.21"
        izz="1.81" />
    </inertial>
    <visual>
      <origin
        xyz="0 0 0"
        rpy="0 0 0" />
      <geometry>
        <mesh
          filename="package://assembly_kuka_simp/meshes/link_1.dae" />
      </geometry>
      <material
        name="orange">
        <color
          rgba="0.64706 0.61961 0.58824 1" />
      </material>
    </visual>
    <collision>
      <origin
        xyz="0 0 0"
        rpy="0 0 0" />
      <geometry>
        <mesh
          filename="package://assembly_kuka_simp/meshes/link_1.dae" />
      </geometry>
    </collision>
  </link>
  
  <joint
    name="base_to_link1"
    type="continuous">
    <origin
      xyz="0 0 0.2255"
      rpy="0 0 1.5686" />
    <parent
      link="base_link" />
    <child
      link="link_1" />
    <axis
      xyz="0 0 1" />
    <limit
      lower="-2.7053"
      upper="2.7053"
      effort="0"
      velocity="2.6878" />
  </joint>

  <link
    name="link_2">
    <inertial>
      <origin
        xyz="0.0031161 -0.17175 0.26406"
        rpy="0 0 0" />
      <mass
        value="63.108" />
      <inertia
        ixx="2.146"
        ixy="0.0017265"
        ixz="-0.018041"
        iyy="2.1873"
        iyz="0.069311"
        izz="0.17296" />
    </inertial>
    <visual>
      <origin
        xyz="0.0031161 -0.17175 0.26406"
        rpy="0 0 0" />
      <geometry>
        <mesh
          filename="package://assembly_kuka_simp/meshes/link_2.dae" />
      </geometry>
      <material
        name="orange">
        <color
          rgba="0.64706 0.61961 0.58824 1" />
      </material>
    </visual>
    <collision>
      <origin
        xyz="0 0 0"
        rpy="0 0 0" />
      <geometry>
        <mesh
          filename="package://assembly_kuka_simp/meshes/link_2.dae" />
      </geometry>
    </collision>
  </link>
  <joint
    name="link1_to_link2"
    type="continuous">
    <origin
      xyz="0.18106 -0.002 0.178"
      rpy="0 0.71824 0" />
    <parent
      link="link_1" />
    <child
      link="link_2" />
    <axis
      xyz="0 1 0" />
    <limit
      lower="-3.1416"
      upper="1.1345"
      effort="0"
      velocity="2.6878" />
  </joint>

  <link
    name="link_3">
    <inertial>
      <origin
        xyz="0.086086 -0.024557 0.10627"
        rpy="0 0 0" />
      <mass
        value="50.39" />
      <inertia
        ixx="0.56851"
        ixy="-0.12841"
        ixz="-0.24829"
        iyy="0.72042"
        iyz="-0.15113"
        izz="0.56576" />
    </inertial>
    <visual>
      <origin
        xyz="0.086086 -0.024557 0.10627"
        rpy="0 0 0" />
      <geometry>
        <mesh
          filename="package://assembly_kuka_simp/meshes/link_3.dae" />
      </geometry>
      <material
        name="orange">
        <color
          rgba="0.64706 0.61961 0.58824 1" />
      </material>
    </visual>
    <collision>
      <origin
        xyz="0 0 0"
        rpy="0 0 0" />
      <geometry>
        <mesh
          filename="package://assembly_kuka_simp/meshes/link_3.dae" />
      </geometry>
    </collision>
  </link>
  <joint
    name="link2_to_link3"
    type="continuous">
    <origin
      xyz="0.0011745 0.002 0.59705"
      rpy="0 -0.58172 0" />
    <parent
      link="link_2" />
    <child
      link="link_3" />
    <axis
      xyz="0 1 0" />
    <limit
      lower="-0.2618"
      upper="2.7576"
      effort="0"
      velocity="3.9794" />
  </joint>

  <link
    name="link_4">
    <inertial>
      <origin
        xyz="0.19879 -0.00067831 0.0004912"
        rpy="0 0 0" />
      <mass
        value="26.395" />
      <inertia
        ixx="0.25277"
        ixy="0.0012247"
        ixz="0.0022768"
        iyy="0.40301"
        iyz="0.052083"
        izz="0.5751" />
    </inertial>
    <visual>
      <origin
        xyz="0.19879 -0.00067831 0.0004912"
        rpy="0 0 0" />
      <geometry>
        <mesh
          filename="package://assembly_kuka_simp/meshes/link_4.dae" />
      </geometry>
      <material
        name="orange">
        <color
          rgba="0.64706 0.61961 0.58824 1" />
      </material>
    </visual>
    <collision>
      <origin
        xyz="0 0 0"
        rpy="0 0 0" />
      <geometry>
        <mesh
          filename="package://assembly_kuka_simp/meshes/link_4.dae" />
      </geometry>
    </collision>
  </link>
  <joint
    name="link3_to_link4"
    type="continuous">
    <origin
      xyz="0.237 0 0.17"
      rpy="-0.77711 0 0" />
    <parent
      link="link_3" />
    <child
      link="link_4" />
    <axis
      xyz="1 0 0" />
    <limit
      lower="-6.1087"
      upper="-6.1087"
      effort="0"
      velocity="5.969" />
  </joint>

  <link
    name="link_5">
    <inertial>
      <origin
        xyz="0.075375 -0.0070921 -1.4828E-07"
        rpy="0 0 0" />
      <mass
        value="8.3316" />
      <inertia
        ixx="0.021249"
        ixy="0.0024931"
        ixz="-1.4695E-07"
        iyy="0.049743"
        iyz="-1.0627E-07"
        izz="0.063119" />
    </inertial>
    <visual>
      <origin
        xyz="0.075375 -0.0070921 -1.4828E-07"
        rpy="0 0 0" />
      <geometry>
        <mesh
          filename="package://assembly_kuka_simp/meshes/link_5.dae" />
      </geometry>
      <material
        name="orange">
        <color
          rgba="0.64706 0.61961 0.58824 1" />
      </material>
    </visual>
    <collision>
      <origin
        xyz="0 0 0"
        rpy="0 0 0" />
      <geometry>
        <mesh
          filename="package://assembly_kuka_simp/meshes/link_5.dae" />
      </geometry>
    </collision>
  </link>
  <joint
    name="link4_to_link5"
    type="continuous">
    <origin
      xyz="0.383 0.005 0"
      rpy="0 0.48037 0" />
    <parent
      link="link_4" />
    <child
      link="link_5" />
    <axis
      xyz="0 1 0" />
    <limit
      lower="-2.2689"
      upper="2.2689"
      effort="0"
      velocity="6.7021" />
  </joint>
  <link
    name="link_6">
    <inertial>
      <origin
        xyz="-0.0010352 -2.6645E-15 -0.00015568"
        rpy="0 0 0" />
      <mass
        value="0.15535" />
      <inertia
        ixx="0.0001313"
        ixy="1.5196E-18"
        ixz="9.2632E-08"
        iyy="6.8352E-05"
        iyz="9.6562E-20"
        izz="6.9057E-05" />
    </inertial>
    <visual>
      <origin
        xyz="-0.0010352 -2.6645E-15 -0.00015568"
        rpy="0 0 0" />
      <geometry>
        <mesh
          filename="package://assembly_kuka_simp/meshes/link_6.dae" />
      </geometry>
      <material
        name="platinum">
        <color
          rgba="0.64706 0.61961 0.58824 1" />
      </material>
    </visual>
    <collision>
      <origin
        xyz="0 0 0"
        rpy="0 0 0" />
      <geometry>
        <mesh
          filename="package://assembly_kuka_simp/meshes/link_6.dae" />
      </geometry>
    </collision>
  </link>
  <joint
    name="link5_to_link6"
    type="continuous">
    <origin
      xyz="0.193 -0.003 0"
      rpy="1.3396 0 0" />
    <parent
      link="link_5" />
    <child
      link="link_6" />
    <axis
      xyz="1 0 0" />
    <limit
      lower="-6.1087"
      upper="6.1087"
      effort="0"
      velocity="12.584" />
  </joint>
</robot>
